Workbook

Sheet Horário - Graduação
C1: =UPPER(E:E) | I1: BACHARELADO EM ENGENHARIA FLORESTAL | O1: BACHARELADO EM SISTEMAS DE INFORMAÇÃO | T1: BACHARELADO EM MEDICINA VETERINÁRIA | Z1: LICENCIATURA EM CIÊNCIAS BIOLÓGICAS | AE1: LICENCIATURA EM FÍSICA | AJ1: LICENCIATURA EM MATEMÁTICA | AO1: LICENCIATURA EM QUÍMICA | AT1: LICENCIATURA EM PEDAGOGIA
A2: DIA | B2: HORÁRIO | C2: 2º PERÍODO Eng. Alimento | D2: 4º PERÍODO Eng. Alimentos | E2: 6º PERÍODO Eng. Alimentos | F2: 8º PERÍODO Eng. Alimentos | G2: 10º PERÍODO Eng. Alimentos | I2: 2º PERÍODO Eng. Florestal | J2: 4º PERÍODO Eng. Florestal | K2: 6º PERÍODO Eng. Florestal | L2: 8º PERÍODO Eng. Florestal | M2: 10º PERÍODO Eng. Florestal | O2: 2º PERÍODO Sist. de Informação | P2: 4º PERÍODO Sist. de Informação | Q2: 6º PERÍODO Sist. de Informação | R2: 8º PERÍODO Sist. de Informação | T2: 2º PERÍODO Med. Veterinária | U2: 4º PERÍODO Med. Veterinária | V2: 6º PERÍODO Med. Veterinária | W2: 8º PERÍODO Med. Veterinária | X2: 10º PERÍODO Med. Veterinária | Z2: 2º PERÍODO Lic. Biológicas | AA2: 4º PERÍODO Lic. Biológicas | AB2: 6º PERÍODO Lic. Biológicas | AC2: 8º PERÍODO Lic. Biológicas | AE2: 2º PERÍODO Lic. Física | AF2: 4º PERÍODO Lic. Física | AG2: 6º PERÍODO Lic. Física | AH2: 8º PERÍODO Lic. Física | AJ2: 2º PERÍODO Lic. Matemática | AK2: 4º PERÍODO Lic. Matemática | AL2: 6º PERÍODO Lic. Matemática | AM2: 8º PERÍODO Lic. Matemática | AO2: 2º PERÍODO Lic. Química | AP2: 4º PERÍODO Lic. Química | AQ2: 6º PERÍODO Lic. Química | AR2: 8º PERÍODO Lic. Química | AT2: 2º PERÍODO Lic. Pedagogia | AU2: 4º PERÍODO Lic. Pedagogia | AV2: 6º PERÍODO Lic. Pedagogia | AW2: 8º PERÍODO Lic. Pedagogia
A3: SEGUNDA | B3: 07:20 - 08:10 | F3: Operações Unitárias III (Isis) (Lab. Fenôm. de Transportes) | I3: Anatomia e Morfologia Vegetal (Jerffson Lucas) (3/7) | K3: Patologia Florestal (Giovanni) (3/8) | L3: Política e Legislação Florestal (Jane Bruna) (3/9) | M3: Gestão Ambiental (optativa) (Élcio José) (3/10) | U3: Parasitologia Veterinária (Fernanda) (HV 2) | V3: UCE 2 (Eduardo Garrido/ Thaís/ Antônio )(HV 3) | W3: Clínica Médica Grandes Animais II (Lídia) (HV 4)
B4: 08:10 - 09:00 | F4: Operações Unitárias III (Isis) (Lab. Fenôm. de Transportes) | I4: Anatomia e Morfologia Vegetal (Jerffson Lucas) (3/7) | K4: Patologia Florestal (Giovanni) (3/8) | L4: Política e Legislação Florestal (Jane Bruna) (3/9) | M4: Gestão Ambiental (optativa) (Élcio José) (3/10) | U4: Parasitologia Veterinária (Fernanda) (HV 2) | V4: UCE 2 (Eduardo Garrido/ Thaís/ Antônio )(HV 3) | W4: Clínica Médica Grandes Animais II (Lídia) (HV 4)
B5: INTERVALO
B6: 09:20 - 10:10 | D6: CÁLCULO III (Viviane) (2/6) | F6: Operações Unitárias III (Isis) (Lab. Fenôm. de Transportes) | I6: Métodos e Técnicas de Estudo e Pesquisa (Jane Bruna) (3/7) | J6: Gênese e Morfologia do Solo (Élcio José) (3/8) | K6: Estrutura Anatômica e Composição da Madeira (Wagner) (Lab. de Madeira) | L6: Melhoramento Florestal (Giovanni) (3/9) | U6: Parasitologia Veterinária (Fernanda) (HV 2) | V6: UCE 2 (Eduardo Garrido/ Thaís/ Antônio )(HV 3) | W6: Clínica Médica Grandes Animais II (Lídia) (HV 4)
B7: 10:10 - 11:00 | D7: CÁLCULO III (Viviane) (2/6) | F7: Operações Unitárias III (Isis) (Lab. Fenôm. de Transportes) | I7: Métodos e Técnicas de Estudo e Pesquisa (Jane Bruna) (3/7) | J7: Gênese e Morfologia do Solo (Élcio José) (3/8) | K7: Estrutura Anatômica e Composição da Madeira (Wagner) (Lab. de Madeira) | L7: Melhoramento Florestal (Giovanni) (3/9) | U7: Parasitologia Veterinária (Fernanda) (HV 2) | V7: UCE 2 (Eduardo Garrido/ Thaís/ Antônio )(HV 3) | W7: Clínica Médica Grandes Animais II (Lídia) (HV 4)
B8: 11:00 - 11:50
B9: ALMOÇO
B10: 13:20 - 14:10 | C10: QUÍMICA ORGÂNICA (Elza) (1/13) | E10: UCE I (Edilson) (1/11) | F10: Planejamento e Projeto (Isis) (Sl. Fenômenos) | I10: QUÍMICA ORGÂNICA (Elza) (1/13) | J10: Entomologia Básica (Tatianne) (3/8) | K10: Hidráulica e Irrigação Aplicada (Marcelo Rossi) (3/7) | L10: Melhoramento Florestal (Giovanni) (3/9) | O10: CÁLCULO DIFERENCIAL E INTEGRAL I (Frederico) (3/10) | P10: Programação Orientada a Objetos I (Leonardo Humberto) (Lab. 1 - Info) | T10: Anatomia Vet. II (Walter)(HV 1) | U10: Nutrição Animal (Antônio) ( HV 2) | V10: UCE 2 (Eduardo Garrido/ Thaís/ Antônio/ Lídia )(HV 3) | W10: Saúde Pública e Saneamento (Vanessa Paulino) (HV 4)
B11: 14:10 - 15:00 | C11: QUÍMICA ORGÂNICA (Elza) (1/13) | E11: UCE I (Edilson) (1/11) | F11: Planejamento e Projeto (Isis) (Sl. Fenômenos) | I11: QUÍMICA ORGÂNICA (Elza) (1/13) | J11: Entomologia Básica (Tatianne) (3/8) | K11: Hidráulica e Irrigação Aplicada (Marcelo Rossi) (3/7) | L11: Melhoramento Florestal (Giovanni) (3/9) | O11: CÁLCULO DIFERENCIAL E INTEGRAL I (Frederico) (3/10) | P11: Programação Orientada a Objetos I (Leonardo Humberto) (Lab. 1 - Info) | T11: Anatomia Vet. II (Walter)(HV 1) | U11: Nutrição Animal (Antônio) ( HV 2) | V11: UCE 2 (Eduardo Garrido/ Thaís/ Antônio/ Lídia )(HV 3) | W11: Saúde Pública e Saneamento (Vanessa Paulino) (HV 4)
B12: INTERVALO
B13: 15:20 - 16:10 | F13: Planejamento e Projeto (Isis) (Sl. Fenômenos) | I13: Introdução à Geologia (Élcio José) (3/7) | J13: Entomologia Básica (Tatianne) (3/8) | K13: Viveiros Florestais (Giovanni) (3/9) | L13: Produtos Florestais (Wagner) (3/10) | O13: Arquitetura de Computadores (Zélia) (Lab. 2 - Info) | P13: Banco de Dados (Patrícia Lucas) (Lab. 4 - Info) | T13: Anatomia Vet. II (Walter)(HV 1) | U13: Nutrição Animal (Antônio) ( HV 2) | V13: Suinocultura (Fernando Matos) (Zoo II)
B14: 16:10 - 17:00 | F14: Planejamento e Projeto (Isis) (Sl. Fenômenos) | I14: Introdução à Geologia (Élcio José) (3/7) | K14: Viveiros Florestais (Giovanni) (3/9) | L14: Produtos Florestais (Wagner) (3/10) | O14: Arquitetura de Computadores (Zélia) (Lab. 2 - Info) | P14: Banco de Dados (Patrícia Lucas) (Lab. 4 - Info) | T14: Anatomia Vet. II (Walter)(HV 1) | U14: Nutrição Animal (Antônio) ( HV 2) | V14: Suinocultura (Fernando Matos) (Zoo II)
B15: 17:00 - 17:50 | D15: ESTATÍSTICA BÁSICA (EAD) (Arilson) (1/10) | P15: Introdução à economia (Mário) (3/9) | R15: Sistemas Distribuídos (Zélia) (Lab. 4 - Info) | AB15: ESTATÍSTICA BÁSICA (EAD) (Agnaldo) | AT15: História da Educação I (Bergston) (2/1) | AW15: UCE VII: Tecendo a FormAÇÃO: ação-reflexãoação (Laio) (2/4)
B16: INTERVALO
B17: 18:10 - 19:00 | D17: ESTATÍSTICA BÁSICA (EAD) (Arilson) (1/10) | P17: Introdução à economia (Mário) (3/9) | R17: Sistemas Distribuídos (Zélia) (Lab. 4 - Info) | AB17: ESTATÍSTICA BÁSICA (EAD) (Agnaldo) | AC17: Estágio Curricular Supervisionado lV (Rosi) (1/8) | AG17: MECÂNICA CLÁSSICA (Luciano) (1/11) | AM17: Estágio Supervisionado IV (Lucas Diego) | AQ17: Estágio Supervisionado IV (Willian Andrade) (Lab. Química II) | AT17: História da Educação I (Bergston)(2/1) | AW17: UCE VII: Tecendo a FormAÇÃO: ação-reflexãoação (Laio) (2/4)
B18: 19:00 - 19:50 | P18: UCE II - Ferramentas Computacionais na Educação (Geycy) (Lab. 1 - Info) | R18: Optativa III - Métodos Ágeis (Zélia) (Lab. 4 - Info) | AA18: Bioquímica (Cristiane) (1/6) | AB18: Investigação Científica (Vanessa Santana) (1/7) | AC18: Tópicos Especiais em Biologia lll (Rosi) (1/8) | AF18: FÍSICA GERAL II (Rafael) (1/10) | AG18: MECÂNICA CLÁSSICA (Luciano) (1/11) | AK18: Tendências em Educação Matemática (Lucas Diego) (LEM) | AM18: Funções de uma variável complexa (Viviane) (1/16) | AQ18: Bioquímica (Cristiane) (1/6) | AR18: Físico-Química III (Magnovaldo) (1/9) | AT18: Relações Étnico-Raciais na Educação Infantil e SIEF (Márlio) (2/1) | AU18: Fundamentos e Metodologia da Matemática na Educação Infantil (Lilian) (2/2) | AV18: Educação do Campo (Patrícia Lima) (2/3) | AW18: Optativa II: Neurociência e Educação (Giuliana) (2/4)
B19: 19:50 - 20:40 | P19: UCE II - Ferramentas Computacionais na Educação (Geycy) (Lab. 1 - Info) | R19: Optativa III - Métodos Ágeis (Zélia) (Lab. 4 - Info) | Z19: Fundamentos filosóficos da Educação (Emille) (1/5) | AA19: Bioquímica (Cristiane) (1/6) | AB19: Investigação Científica (Vanessa Santana) (1/7) | AC19: Prática Pedagógica Xll: Processo de Ensino-Aprendizagem em Ciências e Biologia (Rosi) (1/8) | AF19: FÍSICA GERAL II (Rafael) (1/10) | AG19: MECÂNICA CLÁSSICA (Luciano) (1/11) | AK19: Tendências em Educação Matemática (Lucas Diego) (LEM) | AM19: Funções de uma variável complexa (Viviane) (1/16) | AQ19: Bioquímica (Cristiane) (1/6) | AR19: Físico-Química III (Magnovaldo) (1/9) | AT19: Relações Étnico-Raciais na Educação Infantil e SIEF (Márlio) (2/1) | AU19: Fundamentos e Metodologia da Matemática na Educação Infantil (Lilian) (2/2) | AV19: Educação do Campo (Patrícia Lima) (2/3) | AW19: Optativa II: Neurociência e Educação (Giuliana) (2/4)
B20: INTERVALO
B21: 21:00 - 21:50 | R21: Optativa IV - Tópicos Especiais em Computação I (Geycy) (Lab. 3 - Info) | Z21: Fundamentos filosóficos da Educação (Emille) (1/5) | AA21: Diversidade dos Vegetais (Michellia) (1/6) | AB21: Ecologia de Populações (Tatianne) (1/7) | AC21: Prática Pedagógica Xll: Processo de Ensino-Aprendizagem em Ciências e Biologia (Rosi) (1/8) | AG21: FÍSICA GERAL III (Rodrigo Freitas) (Lab. Física - Rec. Didáticos) | AH21: EVOLUÇÃO DAS IDEIAS DA FÍSICA (Luciano) (1/12) | AK21: Física Geral I (Diego Carvalho / Poliana) (1/14) | AL21: UCE 04 - Projeto Formação de Professores de Matemática (Lucas Diego) (LEM) | AM21: Estatística Básica (Arilson e Agnaldo) (1/16) | AQ21: Físico-Química I (Magnovaldo) (1/12) | AT21: Matemática Básica (Fabiano) (2/1) | AU21: Fundamentos e Metodologia da Matemática na Educação Infantil (Lilian) (2/2) | AV21: Estágio V - Estágio Curricular Supervisionado V: Docência nas SIEF (Giuliana) (2/3) | AW21: UCE VII: Tecendo a FormAÇÃO: ação-reflexãoação (Laio) (2/4)
B22: 21:50 - 22:40 | R22: Optativa IV - Tópicos Especiais em Computação I (Geycy) (Lab. 3 - Info) | AA22: Diversidade dos Vegetais (Michellia) (1/6) | AB22: Ecologia de Populações (Tatianne) (1/7) | AG22: FÍSICA GERAL III (Rodrigo Freitas) (Lab. Física - Rec. Didáticos) | AH22: EVOLUÇÃO DAS IDEIAS DA FÍSICA (Luciano) (1/12) | AK22: Física Geral I (Diego Carvalho / Poliana) (1/14) | AL22: UCE 04 - Projeto Formação de Professores de Matemática (Lucas Diego) (LEM) | AM22: Estatística Básica (Arilson e Agnaldo) (1/16) | AQ22: Físico-Química I (Magnovaldo) (1/12) | AT22: Matemática Básica (Fabiano) (2/1) | AU22: Fundamentos e Metodologia da Matemática na Educação Infantil (Lilian) (2/2) | AV22: Estágio V - Estágio Curricular Supervisionado V: Docência nas SIEF (Giuliana) (2/3) | AW22: UCE VII: Tecendo a FormAÇÃO: ação-reflexãoação (Laio) (2/4)
A23: DIA | B23: HORÁRIO | C23: 2º PERÍODO Eng. Alimento | D23: 4º PERÍODO Eng. Alimentos | E23: 6º PERÍODO Eng. Alimentos | F23: 8º PERÍODO Eng. Alimentos | G23: 10º PERÍODO Eng. Alimentos | I23: 2º PERÍODO Eng. Florestal | J23: 4º PERÍODO Eng. Florestal | K23: 6º PERÍODO Eng. Florestal | L23: 8º PERÍODO Eng. Florestal | M23: 10º PERÍODO Eng. Florestal | O23: 2º PERÍODO Sist. de Informação | P23: 4º PERÍODO Sist. de Informação | Q23: 6º PERÍODO Sist. de Informação | R23: 8º PERÍODO Sist. de Informação | T23: 2º PERÍODO Med. Veterinária | U23: 4º PERÍODO Med. Veterinária | V23: 6º PERÍODO Med. Veterinária | W23: 8º PERÍODO Med. Veterinária | X23: 10º PERÍODO Med. Veterinária | Z23: 2º PERÍODO Lic. Biológicas | AA23: 4º PERÍODO Lic. Biológicas | AB23: 6º PERÍODO Lic. Biológicas | AC23: 8º PERÍODO Lic. Biológicas | AE23: 2º PERÍODO Lic. Física | AF23: 4º PERÍODO Lic. Física | AG23: 6º PERÍODO Lic. Física | AH23: 8º PERÍODO Lic. Física | AJ23: 2º PERÍODO Lic. Matemática | AK23: 4º PERÍODO Lic. Matemática | AL23: 6º PERÍODO Lic. Matemática | AM23: 8º PERÍODO Lic. Matemática | AO23: 2º PERÍODO Lic. Química | AP23: 4º PERÍODO Lic. Química | AQ23: 6º PERÍODO Lic. Química | AR23: 8º PERÍODO Lic. Química | AT23: 2º PERÍODO Lic. Pedagogia | AU23: 4º PERÍODO Lic. Pedagogia | AV23: 6º PERÍODO Lic. Pedagogia | AW23: 8º PERÍODO Lic. Pedagogia
A24: TERÇA | B24: 07:20 - 08:10 | E24: HIGIENE NA INDÚSTRIA DE ALIMENTOS (Bruna Porto) (1/10) | I24: Introdução à Geologia (Élcio José) (3/7) | J24: Fotogrametria e Fotointerpretação (Rodrigo Nogueira) (Sala de Topografia) | K24: Inventário Florestal (Vinícius) (3/8) | L24: Produção e Gestão do Conhecimento (Jerffson Lucas) (3/9) | T24: Fisiologia Animal I (Valéria) (HV 1) | V24: Patologia Clínica Veterinária (Eduardo Garrido) (HV 3) | W24: Clinica Médica de Pequenos Animais II (Thaís) (HV 4)
B25: 08:10 - 09:00 | E25: HIGIENE NA INDÚSTRIA DE ALIMENTOS (Bruna Porto) (1/10) | I25: Introdução à Geologia (Élcio José) (3/7) | J25: Fotogrametria e Fotointerpretação (Rodrigo Nogueira) (Sala de Topografia) | K25: Inventário Florestal (Vinícius) (3/8) | L25: Produção e Gestão do Conhecimento (Jerffson Lucas) (3/9) | T25: Fisiologia Animal I (Valéria) (HV 1) | V25: Patologia Clínica Veterinária (Eduardo Garrido) (HV 3) | W25: Clinica Médica de Pequenos Animais II (Thaís) (HV 4)
B26: INTERVALO
B27: 09:20 - 10:10 | D27: MICROBIOLOGIA (Vanessa Santana) (1/11) | E27: HIGIENE NA INDÚSTRIA DE ALIMENTOS (Bruna Porto) (1/10) | I27: Anatomia e Morfologia Vegetal (Jerffson Lucas) (3/7) | K27: Patologia Florestal (Giovanni) (3/9) | L27: Colheita e Transporte Florestal (Alessandro) (3/10) | M27: Painéis de Madeira, Adesivos e Adesão - Optativa (Wagner) (3/11) | T27: Fisiologia Animal I (Valéria) (HV 1) | U27: Nutrição Animal (Antônio) ( HV 2) | V27: Diagnóstico por Imagem ( Leonardo Coelho) (HV 3) | W27: Clinica Médica de Pequenos Animais II (Thaís) (HV 4)
B28: 10:10 - 11:00 | D28: MICROBIOLOGIA (Vanessa Santana) (1/11) | E28: SECAGEM DE GRÃOS (Jean) (1/12) | I28: Anatomia e Morfologia Vegetal (Jerffson Lucas) (3/7) | K28: Patologia Florestal (Giovanni) (3/9) | L28: Colheita e Transporte Florestal (Alessandro) (3/10) | M28: Painéis de Madeira, Adesivos e Adesão - Optativa (Wagner) (3/11) | T28: Fisiologia Animal I (Valéria) (HV 1) | U28: Nutrição Animal (Antônio) ( HV 2) | V28: Diagnóstico por Imagem ( Leonardo Coelho) (HV 3) | W28: Clinica Médica de Pequenos Animais II (Thaís) (HV 4)
B29: 11:00 - 11:50 | E29: SECAGEM DE GRÃOS (Jean) (1/12) | K29: Sistemas de Informações Geográficas (Rodrigo Nogueira) (Sala de Topografia)
B30: ALMOÇO
B31: 13:20 - 14:10 | C31: MATÉRIAS PRIMAS ALIMENTÍCIAS (Bruna Porto) (1/13) | D31: Física II (Diego Carvalho) (1/7) | E31: TECNOLOGIA DE CARNES (Felipe Cimino) (2/6) | F31: UCE III (Andreia) (1/17) | I31: Sociologia e Extensão RuralSociologia e Extensão Rural (Patrícia Lima) (3/7) | J31: Gênese e Morfologia do Solo (Élcio José) (3/8) | K31: Sistemas de Informações Geográficas (Rodrigo Nogueira) (Sala de Topografia) | L31: Política e Legislação Florestal (Jane Bruna) (3/9) | O31: CÁLCULO DIFERENCIAL E INTEGRAL I (Frederico) (3/10) | P31: Programação Orientada a Objetos I (Leonardo Humberto) (Lab. 2 - Info) | Q31: UCE IV - Projeto de Sistemas de Informação (Danielle Miranda) (Lab. 4 - Info) | T31: Histologia (Fernanda) (HV 1) | U31: Patologia Geral (Eduardo Garrido) (HV 2) | V31: Doenças Parasitárias (Vanessa Paulino) (HV 3) | W31: Cirurgia e Obstetrícia (Walter) (HV 4)
B32: 14:10 - 15:00 | C32: MATÉRIAS PRIMAS ALIMENTÍCIAS (Bruna Porto) (1/13) | D32: Física II (Diego Carvalho) (1/7) | E32: TECNOLOGIA DE CARNES (Felipe Cimino) (2/6) | F32: UCE III (Andreia) (1/17) | I32: Sociologia e Extensão RuralSociologia e Extensão Rural (Patrícia Lima) (3/7) | J32: Gênese e Morfologia do Solo (Élcio José) (3/8) | K32: Sistemas de Informações Geográficas (Rodrigo Nogueira) (Sala de Topografia) | L32: Política e Legislação Florestal (Jane Bruna) (3/9) | O32: CÁLCULO DIFERENCIAL E INTEGRAL I (Frederico) (3/10) | P32: Programação Orientada a Objetos I (Leonardo Humberto) (Lab. 2 - Info) | Q32: UCE IV - Projeto de Sistemas de Informação (Danielle Miranda) (Lab. 4 - Info) | T32: Histologia (Fernanda) (HV 1) | U32: Patologia Geral (Eduardo Garrido) (HV 2) | V32: Doenças Parasitárias (Vanessa Paulino) (HV 3) | W32: Cirurgia e Obstetrícia (Walter) (HV 4)
B33: INTERVALO
B34: 15:20 - 16:10 | C34: QUÍMICA ORGÂNICA (Elza) (1/13) | E34: TECNOLOGIA DE CARNES (Felipe Cimino) (2/6) | F34: UCE III (Andreia) (1/17) | I34: QUÍMICA ORGÂNICA (Elza) (1/13) | K34: UCE II (Jerffson Lucas) (Sala de Topografia) | L34: Construções de Madeira (Alessandro) (3/11) | M34: Gestão Ambiental (optativa) (Élcio José) (3/8) | O34: CÁLCULO DIFERENCIAL E INTEGRAL I (Frederico) (3/10) | P34: Engenharia de Software II (Danielle Miranda) (Lab. 2 - Info) | T34: Histologia (Fernanda) (HV 1) | U34: Patologia Geral (Eduardo Garrido) (HV 2) | V34: Doenças Parasitárias (Vanessa Paulino) (HV 3) | W34: Cirurgia e Obstetrícia (Walter) (HV 4)
B35: 16:10 - 17:00 | C35: QUÍMICA ORGÂNICA (Elza) (1/13) | E35: TECNOLOGIA DE CARNES (Felipe Cimino) (2/6) | I35: QUÍMICA ORGÂNICA (Elza) (1/13) | K35: UCE II (Jerffson Lucas) (Sala de Topografia) | L35: Construções de Madeira (Alessandro) (3/11) | M35: Gestão Ambiental (optativa) (Élcio José) (3/8) | O35: CÁLCULO DIFERENCIAL E INTEGRAL I (Frederico) (3/10) | P35: Engenharia de Software II (Danielle Miranda) (Lab. 2 - Info) | T35: Histologia (Fernanda) (HV 1) | U35: Patologia Geral (Eduardo Garrido) (HV 2) | V35: Doenças Parasitárias (Vanessa Paulino) (HV 3) | W35: Cirurgia e Obstetrícia (Walter) (HV 4)
B36: 17:00 - 17:50 | D36: ESTATÍSTICA BÁSICA (EAD) (Agnaldo) | K36: UCE II (Jane Bruna) (Sala de Topografia) | O36: Algoritmos e Estruturas de Dados II (Alison Zille) (Lab. 1 - Info) | P36: Banco de Dados (Patrícia Lucas) (Lab. 2 - Info) | Q36: Optativa I - Sistemas de Apoi à Decisão (Zélia) (Lab. 4 - Info) | R36: Optativa IV - Tópicos Especiais em Computação I (Geycy) (Lab. 3 - Info) | AB36: ESTATÍSTICA BÁSICA (EAD) (Agnaldo) | AC36: Prática Pedagógica V: Laboratório de Genética (Turma Extra Pré Horário) (Vanessa Santana) | AK36: UCE 02 - Projeto Tecnologias na Educação (Viviane) (1/14) | AO36: Laboratório de Química Geral II (Bruno) (Lab. Química I) | AQ36: Unidade Curricular de Extensão (UCE) II (Cristiane) (1/9) | AU36: Pesquisa e Prática Pedagógica IV (Giuliana) (2/2) | AW36: Educação: Corpo e Ludicidade (Jairo / Fabiene) (2/4)
B37: INTERVALO
B38: 18:10 - 19:00 | D38: ESTATÍSTICA BÁSICA (EAD) (Agnaldo) | K38: UCE II (Jane Bruna) (Sala de Topografia) | O38: Algoritmos e Estruturas de Dados II (Alison Zille) (Lab. 1 - Info) | P38: Banco de Dados (Patrícia Lucas) (Lab. 2 - Info) | Q38: Optativa I - Sistemas de Apoi à Decisão (Zélia) (Lab. 4 - Info) | R38: Optativa IV - Tópicos Especiais em Computação I (Geycy) (Lab. 3 - Info) | AB38: ESTATÍSTICA BÁSICA (EAD) (Agnaldo) | AC38: Prática Pedagógica V: Laboratório de Genética (Turma Extra Pré Horário) (Vanessa Santana) (1/8) | AG38: ESTÁGIO CURRICULAR SUPERVISIONADO II (Emille) (1/11) | AH38: FÍSICA CONTEMPORÂNEA (Luciano) (1/12) | AK38: UCE 02 - Projeto Tecnologias na Educação (Viviane) (1/14) | AL38: Estágio Supervisionado II (120 h/a) (Lucas Diego) (LEM) | AO38: Laboratório de Química Geral II (Bruno) (Lab. Química I) | AQ38: Unidade Curricular de Extensão (UCE) II (Cristiane) (1/9) | AU38: Pesquisa e Prática Pedagógica IV (Giuliana) (2/2) | AW38: Educação: Corpo e Ludicidade (Jairo / Fabiene) (2/4)
B39: 19:00 - 19:50 | P39: Introdução à economia (Mário) (3/9) | Q39: Metodologia Científica (Geycy) (Lab. 2 - Info) | R39: Sistemas Distribuídos (Zélia) (Lab. 4 - Info) | Z39: Histologia (Valéria) (1/5) | AA39: Parasitologia (Filipe) (1/6) | AB39: ESTATÍSTICA BÁSICA (EAD) (Arilson) | AC39: Educação Profissional (Laio) (1/8) | AF39: Cálculo Diferencial e integral III (Eilson Santiago) (1/11) | AG39: UCE IV - ROBÓTICA EDUCACIONAL (Rodrigo Freitas) (1/11) | AH39: FÍSICA CONTEMPORÂNEA (Luciano) (1/12) | AJ39: Geometria Euclidiana Plana (oferta especial) (Aldemi) (1/13) | AK39: UCE 02 - Projeto Tecnologias na Educação (Viviane) (LEM) | AL39: Cálculo Diferencial e integral III (Eilson Santiago) (1/11) | AM39: Educação Profissional (Laio) (1/16) | AP39: Análise Orgânica (Bruno) (1/17) | AR39: Educação Profissional (Laio) (1/16) | AT39: Letramento (s): Dimensão Plural (Cláudia) (2/1) | AU39: Estágio Supervisionado III: Alfabetização e Avaliações Institucionais (Edna / Admilson) (2/2) | AV39: Gestão da Educação em espaços não escolares (Emille) (2/3) | AW39: Organização da Educação Brasileira (Gerson) (2/5)/ Optativa II: Pedagogia Empresarial (Lilian) (2/4)
B40: 19:50 - 20:40 | P40: Introdução à economia (Mário) (3/9) | Q40: Metodologia Científica (Geycy) (Lab. 2 - Info) | R40: Sistemas Distribuídos (Zélia)(Lab. 4 - Info) | Z40: Histologia (Valéria) (1/5) | AA40: Parasitologia (Filipe) (1/6) | AB40: Ecologia de Populações (Tatianne) (1/7) | AC40: Educação Profissional (Laio) (1/8) | AF40: Cálculo Diferencial e integral III (Eilson Santiago) (1/11) | AG40: UCE IV - ROBÓTICA EDUCACIONAL (Rodrigo Freitas) (1/11) | AH40: FÍSICA CONTEMPORÂNEA (Luciano) (1/12) | AJ40: Geometria Euclidiana Plana (oferta especial) (Aldemi) (1/13) | AK40: UCE 02 - Projeto Tecnologias na Educação (Viviane) (1/14) | AL40: Cálculo Diferencial e integral III (Eilson Santiago) (1/11) | AM40: Educação Profissional (Laio)(1/16) | AP40: Análise Orgânica (Bruno) (1/17) | AR40: Educação Profissional (Laio) (1/16) | AT40: Letramento (s): Dimensão Plural (Cláudia) (2/1) | AU40: UCE IV: Alfaletrar: Práticas de Alfabetização na Escola (Admilson e Giuliana) (2/2) | AV40: Gestão da Educação em espaços não escolares (Emille) (2/3) | AW40: Organização da Educação Brasileira (Gerson) (2/5)/ Optativa II: Pedagogia Empresarial (Lilian) (2/4)
...

Sheet Horário - Ensino Médio
A1: E | C1: AGROINDÚSTRIA | J1: AGROPECUÁRIA | Q1: INFORMÁTICA | X1: QUÍMICA | Z1: MEIO AMBIENTE
A2: DIA | B2: HORÁRIO | C2: 1º ANO A Agroindústria | D2: 1º ANO B Agroindústria | E2: 2º ANO A Agroindústria | F2: 2º ANO B Agroindústria | G2: 3º ANO A Agroindústria | H2: 3º ANO B Agroindústria | J2: 1º ANO A Agropecuária | K2: 1º ANO B Agropecuária | L2: 2º ANO A Agropecuária | M2: 2º ANO B Agropecuária | N2: 3º ANO A Agropecuária | O2: 3º ANO B Agropecuária | Q2: 1º ANO A Informática | R2: 1º ANO B Informática | S2: 2º ANO A Informática | T2: 2º ANO B Informática | U2: 3º ANO A Informática | V2: 3º ANO B Informática | X2: 1º ANO Química | Z2: 1º ANO - Meio Ambiente
A3: SEGUNDA-FEIRA | B3: 07:20 - 08:10 | C3: Química (Juliana Diniz) (Mini 1) | D3: Biologia (Érica)(2/2) | E3: Laboratório II(Anál. sensorial e Anál. F.Q) (Alexandre) (Sl. Análise Sensorial) | F3: Ed. Física (Gera Jr.) | G3: Tecnologia de Leite (Ramon) (Agroin. 1) | H3: Física (Rafael) (1/13) | J3: Agricultura Geral e Olericultura (Cani) (3/11) | K3: História (Crhistophe) (2/3) | L3: Desemho Téc. e Topografia (Rodrigo Nogueira) (Sala de Topografia) | M3: Culturas Anuais e Forragicultura (Leandro) (Agricult. II) | N3: Química (Magnovaldo) (1/14) | O3: Irrigação e Drenagem (Marcelo Rossi) (1/15) | Q3: Filosofia (Lucas Fernando) (2/4) | R3: Língua Espanhola (Luana) (2/5) | S3: Geografia (Márcia Martins) (1/10) | T3: Sociologia (Márlio) (1/11) | U3: Matemática (Nilsa)(1/16) | V3: Biologia (Rosi) (1/17) | X3: Geografia (Tiago Caminha)(1/4)
B4: 08:10 - 09:00 | C4: Química (Juliana Diniz) (2/1) | D4: Biologia (Érica)(2/2) | E4: Laboratório II(Anál. sensorial e Anál. F.Q) (Alexandre) (Sl. Análise Sensorial) | F4: Ed. Física (Gera Jr.) | G4: Tecnologia de Leite (Ramon)(Agroin. 1) | H4: Física (Rafael) (1/13) | J4: Agricultura Geral e Olericultura (Cani) (3/11) | K4: História (Crhistophe) (2/3) | L4: Desemho Téc. e Topografia (Rodrigo Nogueira) (Sala de Topografia) | M4: Culturas Anuais e Forragicultura (Leandro) (Agricult. II) | N4: Química (Magnovaldo) (1/14) | O4: Irrigação e Drenagem (Marcelo Rossi) (1/15) | R4: Filosofia (Lucas Fernando) (2/5) | S4: Geografia (Márcia Martins) (1/10) | T4: Sociologia (Márlio) (1/11) | U4: Matemática (Nilsa)(1/16) | V4: Biologia (Rosi) (1/17) | X4: Geografia (Tiago Caminha)(1/4) | Z4: Língua Espanhola (Luana)(1/5)
B5: INTERVALO
B6: 09:20 - 10:10 | C6: Matemática (Fabiano) (2/1) | D6: Física (Rafael) (2/2) | E6: Geografia (Márcia Martins)(1/6) | F6: Laboratório II(Anál. sensorial e Anál. F.Q) (Alexandre) (Sl. Análise Sensorial) | G6: Tecnologia de Leite (Ramon) (Agroin. 1) | H6: Sociologia (Márlio)(1/13) | J6: Agricultura Geral e Olericultura (Cani) (3/11) | K6: Filosofia (Lucas Fernando) (2/3) | L6: Culturas Anuais e Forragicultura (Leandro) (Agricult. II) | M6: Desemho Téc. e Topografia (Rodrigo Nogueira) (Sala de Topografia) | N6: Irrigação e Drenagem (Marcelo Rossi) (1/14) | O6: Química (Magnovaldo) (1/15) | Q6: Língua Espanhola (Luana) (2/4) | R6: Biologia (Érica)(2/5) | S6: Des. de sistema (Leonardo Humberto) (Lab. 1 - Info) | T6: Montagem e Manut. (Geycy) (Lab. 3 - Info) | U6: História (Renata) (1/16) | V6: Matemática (Nilsa) (1/17) | X6: Educação Física (Jairo) | Z6: História (Crhistophe) (1/5)
B7: 10:10 - 11:00 | C7: Língua Espanhola (Luana)(2/1) | D7: Química (Juliana Diniz)(2/2) | E7: Geografia (Márcia Martins)(1/6) | F7: Laboratório II(Anál. sensorial e Anál. F.Q) (Alexandre) (Sl. Análise Sensorial) | G7: Biologia (Rosi) (1/12) | H7: Matemática (Nilsa) (1/13) | J7: Agricultura Geral e Olericultura (Cani) (3/11) | L7: Culturas Anuais e Forragicultura (Leandro) (Agricult. II) | M7: Desemho Téc. e Topografia (Rodrigo Nogueira) (Sala de Topografia) | N7: Irrigação e Drenagem (Marcelo Rossi) (1/14) | O7: Química (Magnovaldo) (1/15) | Q7: Geografia (Tiago Caminha)(2/4) | R7: Biologia (Érica)(2/5) | S7: Des. de sistema (Leonardo Humberto) (Lab. 1 - Info) | T7: Montagem e Manut. (Geycy) (Lab. 3 - Info) | U7: História (Renata) (1/16) | X7: Educação Física (Jairo) | Z7: Filosofia (Lucas Fernando)(1/5)
B8: 11:00 - 11:50 | C8: Matemática (Fabiano) (2/1) | D8: Química (Juliana Diniz)(2/2) | E8: Física (Rodrigo Freitas) (1/6) | G8: Biologia (Rosi) (1/12) | H8: Matemática (Nilsa) (1/13) | J8: Filosofia (Lucas Fernando) (2/3) | L8: Geografia (Márcia Martins)(1/8) | M8: Língua Portuguesa(Luana) (1/9) | N8: Biologia (Érica) (1/14) | O8: Matemática (Viviane)(1/15) | Q8: Geografia (Tiago Caminha)(2/4) | S8: Sociologia (Márlio) (1/10) | T8: Montagem e Manut. (Geycy) (Lab. 3 - Info) | V8: História (Renata) (1/17) | Z8: Física (Rafael)(1/4)
B9: ALMOÇO
B10: 13:20 - 14:10 | C10: Matemática (Fabiano) (2/1) | D10: História (Crhistophe)(2/2) | E10: Língua Estrangeira (Carla/André Canela) (CELIN 1) | F10: Língua Estrangeira (Thaís Rios/André Canela) (CELIN 3) | G10: História (Renata) (1/12) | H10: Tecnologia de Leite (Ramon) (Agroin. 1) | K10: Educação Física (Jairo) | L10: Sociologia (Patrícia Lima) (1/8) | M10: Língua Portuguesa(Luana) (1/9) | N10: Cult. Perenes e Fruticultura (Leandro) (Agricult. III) | O10: Filosofia (Admilson) (2/6) | Q10: Química (Juliana Diniz)(2/4) | R10: Geografia (Tiago Caminha)(2/5) | S10: Sociologia (Márlio) (1/10) | T10: Educação Física (Gera Jr.) | U10: Filosofia (Lucas Fernando) (1/16) | V10: Física (Rafael) (1/17) | X10: Biologia (Érica)(1/4) | Z10: Biologia (Lays)(1/5)
B11: 14:10 - 15:00 | C11: Biologia (Érica)(2/1) | D11: História (Crhistophe)(2/2) | E11: Língua Estrangeira (Carla/André Canela) (CELIN 1) | F11: Língua Estrangeira (Thaís Rios/André Canela) (CELIN 3) | G11: História (Renata) (1/12) | H11: Tecnologia de Leite (Ramon) (Agroin. 1) | K11: Educação Física (Jairo) | L11: Sociologia (Patrícia Lima) (1/8) | M11: Geografia (Márcia Martins)(1/9) | N11: Cult. Perenes e Fruticultura (Leandro) (Agricult. III) | O11: Filosofia (Admilson) (2/6) | Q11: Química (Juliana Diniz)(2/4) | R11: Geografia (Tiago Caminha)(2/5) | S11: Montagem e Manut. (Geycy) (Lab. 3 - Info) | T11: Educação Física (Gera Jr.) | U11: Filosofia (Lucas Fernando) (1/16) | V11: Física (Rafael) (1/17) | X11: Língua Espanhola (Luana)(1/4) | Z11: Biologia (Lays)(1/5)
B12: INTERVALO
B13: 15:20 - 16:10 | C13: História (Crhistophe)(2/1) | D13: Matemática (Fabiano) (2/2) | E13: Biologia (Marinalva / Vanessa Santana)(1/6) | F13: Geografia (Márcia Martins) (1/7) | G13: Matemática (Nilsa) (1/12) | H13: Tecnologia de Leite (Ramon) (Agroin. 1) | J13: Geografia (Tiago Caminha) (2/3) | K13: Biologia (Érica) (2/4) | L13: Língua Estrangeira (Carla/Luana) (CELIN 1) | M13: Língua Estrangeira (Thaís Rios/Luana) (CELIN 2) | N13: Filosofia (Admilson) (2/6) | O13: Cult. Perenes e Fruticultura (Leandro) (Agricult. III) | Q13: Educação Física (Jairo) | R13: Química (Juliana Diniz)(2/5) | S13: Montagem e Manut. (Geycy) (Lab. 3 - Info) | T13: Des. de sistema (Leonardo Humberto) (Lab. 1 - Info) | U13: Física (Rafael) (1/16) | V13: Filosofia (Lucas Fernando) (1/17) | X13: Mineralogia (Elza) (1/4) | Z13: Matemática (Frederico)(1/5)
B14: 16:10 - 17:00 | C14: História (Crhistophe)(2/1) | D14: Matemática (Fabiano) (2/2) | E14: Biologia (Marinalva / Vanessa Santana)(1/6) | F14: Geografia (Márcia Martins) (1/7) | G14: Matemática (Nilsa) (1/12) | J14: Geografia (Tiago Caminha) (2/3) | K14: Biologia (Érica)(2/4) | L14: Língua Estrangeira (Carla/Luana) (CELIN 1) | M14: Língua Estrangeira (Thaís Rios/Luana) (CELIN 2) | N14: Filosofia (Admilson) (2/6) | O14: Cult. Perenes e Fruticultura (Leandro) (Agricult. III) | Q14: Educação Física (Jairo) | R14: Química (Juliana Diniz)(2/5) | S14: Montagem e Manut. (Geycy) (Lab. 3 - Info) | T14: Des. de sistema (Leonardo Humberto) (Lab. 1 - Info) | U14: Física (Rafael) (1/16) | V14: Filosofia (Lucas Fernando) (1/17) | X14: Mineralogia (Elza) (1/4) | Z14: Matemática (Frederico)(1/5)
B15: 17:00 - 17:50
B16: 18:10 - 19:00
A17: DIA | B17: HORÁRIO | C17: 1º ANO A - Agroindústria | D17: 1º ANO B - Agroindústria | E17: 2º ANO A - Agroindústria | F17: 2º ANO B - Agroindústria | G17: 3º ANO A - Agroindústria | H17: 3º ANO B - Agroindústria | J17: 1º ANO A - Agropecuária | K17: 1º ANO B - Agropecuária | L17: 2º ANO A - Agropecuária | M17: 2º ANO B - Agropecuária | N17: 3º ANO A - Agropecuária | O17: 3º ANO B - Agropecuária | Q17: 1º ANO A - Informática | R17: 1º ANO B - Informática | S17: 2º ANO A - Informática | T17: 2º ANO B - Informática | U17: 3º ANO A - Informática | V17: 3º ANO B - Informática | X17: 1º ANO - Química | Z17: 1º ANO - Meio Ambiente
A18: TERÇA-FEIRA | B18: 07:20 - 08:10 | C18: Ciência e Tecnologia de Produtos de Origem Vegetal (Andreia) (Agroin. 2) | D18: Filosofia (Lucas Fernando) (2/2) | E18: Laboratório II(Anál. sensorial e Anál. F.Q) (Daniela) (Sl. Análise Sensorial) | F18: Química (Cristiane)(1/7) | G18: Anál. de Alim. (Alexandre) (Lab. Bromatologia) | H18: Geografia (Tiago Caminha)(1/13) | J18: Biologia (Érica) (2/3) | K18: Agricultura Geral e Olericultura (Cani) (3/11) | L18: Língua Portuguesa (Luana)(1/8) | M18: Sociologia (Patrícia Lima) (1/9) | N18: Geografia (Márcia Martins)(1/14) | O18: Produção de Ruminantes (Sérgio) (Zoo III) | Q18: Software (Patrícia Lucas) (2/4) | R18: Educação Física (Jairo) | S18: Anál. e Proj. de sist. (Danielle Miranda) (Lab. 4 - Info) | T18: Des. de sistema (Leonardo Humberto) (Lab. 1 - Info) | U18: Matemática (Nilsa) (1/16) | V18: História (Renata) (1/17) | X18: Matemática (Eilson Santiago)(1/4) | Z18: Matemática (Frederico) (1/5)
B19: 08:10 - 09:00 | C19: Ciência e Tecnologia de Produtos de Origem Vegetal (Andreia) (Agroin. 2) | D19: Matemática (Fabiano) (2/2) | E19: Laboratório II(Anál. sensorial e Anál. F.Q) (Daniela) (Sl. Análise Sensorial) | F19: Química (Cristiane) (1/7) | G19: Anál. de Alim. (Alexandre) (Lab. Bromatologia) | H19: Geografia (Tiago Caminha)(1/13) | J19: Biologia (Érica) (2/3) | K19: Agricultura Geral e Olericultura (Cani) (3/11) | L19: Língua Portuguesa (Luana)(1/8) | M19: Sociologia (Patrícia Lima) (1/9) | N19: Geografia (Márcia Martins)(1/14) | O19: Produção de Ruminantes (Sérgio) (Zoo III) | Q19: Software (Patrícia Lucas) (2/4) | R19: Educação Física (Jairo) | S19: Anál. e Proj. de sist. (Danielle Miranda) (Lab. 4 - Info) | T19: Des. de sistema (Leonardo Humberto) (Lab. 1 - Info) | U19: Biologia (Rosi) (1/16) | V19: Matemática (Nilsa) (1/17) | X19: Matemática (Eilson Santiago)(1/4) | Z19: Matemática (Frederico) (1/5)
B20: INTERVALO
B21: 09:20 - 10:10 | C21: Ciência e Tecnologia de Produtos de Origem Vegetal (Andreia) (Agroin. 2) | D21: Língua Portuguesa (Ana Clara) (2/2) | E21: Ciência e Tecnologia de Produtos de Origem animal (Ramon) (Agroin. 1) | F21: Laboratório II(Anál. sensorial e Anál. F.Q) (Daniela) (Sl. Análise Sensorial) | G21: Anál. de Alim. (Alexandre) (Lab. Bromatologia) | H21: História (Renata) (1/13) | J21: Líng. espanhola (Luana) (2/3) | K21: Agricultura Geral e Olericultura (Cani) (3/11) | L21: Geografia (Márcia Martins)(1/8) | M21: Produção de Monogástricos (Fernando Matos) (Zoo II) | N21: Cult. Perenes e Fruticultura (Leandro) (Agricult. III) | O21: Produção de Ruminantes (Sérgio) (Zoo III) | R21: Software (Patrícia Lucas) (2/6) | S21: Des. de sistema (Leonardo Humberto) (Lab. 1 - Info) | T21: Anál. e Proj. de sist. (Danielle Miranda) (Lab. 4 - Info) | U21: Biologia (Rosi) (1/16) | V21: Matemática (Nilsa)(1/17) | X21: Laboratório em Química (Luiz Fernando /Elza) | Z21: Microbiologia Ambiental (Érica)
B22: 10:10 - 11:00 | C22: Gestão da qualidade (Bruna Porto)(2/1) | D22: Geografia (Tiago Caminha) (2/2) | E22: Ciência e Tecnologia de Produtos de Origem animal (Ramon) (Agroin. 1) | F22: Laboratório II(Anál. sensorial e Anál. F.Q) (Daniela) (Sl. Análise Sensorial) | G22: Língua Estrangeira (Carla/André Canela) (CELIN 1) | H22: Língua Estrangeira (Thaís Rios/André Canela) (CELIN 3) | J22: História (Renata) (2/3) | K22: Agricultura Geral e Olericultura (Cani) (3/11) | L22: Biologia (Lays)(1/8) | M22: Produção de Monogástricos (Fernando Matos) (Zoo II) | N22: Cult. Perenes e Fruticultura (Leandro) (Agricult. III) | O22: Produção de Ruminantes (Sérgio) (Zoo III) | Q22: Biologia (Érica) (2/4) | R22: Software (Patrícia Lucas) (2/6) | S22: Des. de sistema (Leonardo Humberto) (Lab. 1 - Info) | T22: Anál. e Proj. de sist. (Danielle Miranda) (Lab. 4 - Info) | V22: Língua Portuguesa (Ana Clara) (1/17) | X22: Laboratório em Química (Luiz Fernando /Elza) | Z22: Língua Portuguesa (Willian Fernandes)(1/5)
B23: 11:00 - 11:50 | C23: Filosofia (Lucas Fernando)(2/1) | D23: Geografia (Tiago Caminha) (2/2) | E23: Ciência e Tecnologia de Produtos de Origem animal (Ramon) (Agroin. 1) | F23: Literatura (Wesley) (1/7) | G23: Língua Estrangeira (Carla/André Canela) (CELIN 1) | H23: Língua Estrangeira (Thaís Rios/André Canela) (CELIN 3) | J23: História (Renata) (2/3) | K23: Língua Espanhola (Luana) (2/6) | L23: Biologia (Lays)(1/8) | M23: Geografia (Márcia Martins)(1/9) | N23: Matemática (Nilsa) (1/14) | O23: Biologia (Érica)(1/15) | S23: Matemática (Aldemi) (1/10) | T23: Língua Portuguesa (Patrícia Ramires) (1/11) | V23: Língua Portuguesa (Ana Clara) (1/17) | X23: Laboratório em Química (Luiz Fernando /Elza) | Z23: Língua Portuguesa (Willian Fernandes)(1/5)
B24: ALMOÇO
B25: 13:20 - 14:10 | C25: Ciência e Tecnologia de Produtos de Origem Vegetal (Márcia Antunes) (Agroin. 2) | D25: Educação Física (Jairo) | E25: Língua Portuguesa (Patrícia Ramires) (1/6) | F25: Ciência e Tecnologia de Produtos de Origem animal (Ramon) (Agroin. 1) | G25: Geografia (Márcia Martins) (1/12) | H25: Anál. de Alim. (Alexandre) (Lab. Bromatologia) | J25: Desenvolv. Ext. Rural (Márlio)(2/3) | K25: Geografia (Tiago Caminha) (2/3) | L25: Matemática (Eilson Santiago) (1/8) | M25: Ed. Física (Gera Jr.) | N25: Língua Estrangeira (Carla/André Canela) (CELIN 1) | O25: Língua Estrangeira (Thaís Rios/André Canela) (CELIN 3) | Q25: Algorítmos (Alison Zille) (Lab. 3 - Info) | R25: História (Bergston) (2/5) | S25: Literatura (Wesley) (1/10) | T25: Matemática (Aldemi) (1/11) | U25: Desenvolv. WEB (Arthur) (Lab. 1 - Info) | X25: Filosofia (Lucas Fernando)(1/4)
B26: 14:10 - 15:00 | C26: Ciência e Tecnologia de Produtos de Origem Vegetal (Márcia Antunes) (Agroin. 2) | D26: Educação Física (Jairo) | E26: Literatura (Wesley) (1/6) | F26: Ciência e Tecnologia de Produtos de Origem animal (Ramon) (Agroin. 1) | G26: Geografia (Márcia Martins) (1/12) | H26: Anál. de Alim. (Alexandre) (Lab. Bromatologia) | J26: Desenvolv. Ext. Rural (Márlio)(2/3) | K26: Geografia (Tiago Caminha) (2/3) | L26: Matemática (Eilson Santiago) (1/8) | M26: Ed. Física (Gera Jr.) | N26: Língua Estrangeira (Carla/André Canela) (CELIN 1) | O26: Língua Estrangeira (Thaís Rios/André Canela) (CELIN 3) | Q26: Algorítmos (Alison Zille) (Lab. 3 - Info) | R26: História (Bergston) (2/5) | S26: Língua Portuguesa (Patrícia Ramires) (1/10) | T26: Matemática (Aldemi) (1/11) | U26: Desenvolv. WEB (Arthur) (Lab. 1 - Info) | V26: Arte (Jamerson Rezende) | X26: Língua Portuguesa (Willian Fernandes)(1/4)
B27: INTERVALO
B28: 15:20 - 16:10 | C28: Ciência e Tecnologia de Produtos de Origem Vegetal (Márcia Antunes) (Agroin. 2) | D28: Matemática e Português para o Cotidiano (Roberta, Fabiano, Evelyn) (2/2) | E28: Ciência da Natureza (Isis, Aline, Marinalva, Clayton) (Sl. Análise Sensorial) | F28: Ciência e Tecnologia de Produtos de Origem animal (Ramon) (Agroin. 1) | G28: Filosofia (Admilson)(2/6) | H28: Anál. de Alim. (Alexandre) (Lab. Bromatologia) | J28: Educação Física (Jairo) | K28: Literatura (Wesley)(2/3) | L28: Produção de Monogástricos (Fernando Matos) (Zoo II) | M28: Biologia (Lays) (1/9) | N28: Língua Portuguesa (Willian Fernandes) (1/14) | O28: Geografia (Tiago Caminha)(1/15) | Q28: História (Bergston) (2/4) | R28: Algorítmos (Alison Zille) (Lab. 3 - Info) | S28: Fundamentos do Design e Webdesign (Jamerson Rezende) (Lab. 4 - Info) | T28: Geografia (Márcia Martins) (1/11) | U28: Língua estrangeira (Carla/André Canela) (CELIN 1) | V28: Desenvolv. WEB (Arthur) (Lab. 1 - Info) | X28: Estatística Aplicada (Rodrigo Freitas) (1/4) | Z28: Introdução ao Estudo do Meio Ambiente (Jane Bruna, Vinícius)(1/5)
B29: 16:10 - 17:00 | C29: Matemática e Português para o Cotidiano (Roberta, Fabiano, Evelyn) (2/1) | D29: Física (Rafael) (2/2) | E29: Matemática (Aldemi) (1/6) | F29: Ciência da Natureza (Isis, Aline, Marinalva, Clayton) (Sl. Análise Sensorial) | G29: Matemática (Nilsa) (1/12) | H29: Filosofia (Admilson)(2/6) | J29: Educação Física (Jairo) | K29: Literatura (Wesley)(2/3) | L29: Produção de Monogástricos (Fernando Matos) (Zoo II) | M29: Biologia (Lays) (1/9) | N29: Língua Portuguesa (Willian Fernandes) (1/14) | O29: Geografia (Tiago Caminha)(1/15) | Q29: História (Bergston) (2/4) | R29: Algorítmos (Alison Zille) (Lab. 3 - Info) | S29: Fundamentos do Design e Webdesign (Jamerson Rezende) (Lab. 4 - Info) | T29: Geografia (Márcia Martins) (1/11) | U29: Língua estrangeira (Carla/André Canela) (CELIN 1) | V29: Desenvolv. WEB (Arthur) (Lab. 1 - Info) | X29: História (Renata) (1/4) | Z29: Introdução ao Estudo do Meio Ambiente (Jane Bruna, Vinícius)(1/5)
B30: 17:00 - 17:50
B31: 18:10 - 19:00
A32: DIA | B32: HORÁRIO | C32: 1º ANO A - Agroindústria | D32: 1º ANO B - Agroindústria | E32: 2º ANO A - Agroindústria | F32: 2º ANO B - Agroindústria | G32: 3º ANO A - Agroindústria | H32: 3º ANO B - Agroindústria | J32: 1º ANO A - Agropecuária | K32: 1º ANO B - Agropecuária | L32: 2º ANO A - Agropecuária | M32: 2º ANO B - Agropecuária | N32: 3º ANO A - Agropecuária | O32: 3º ANO B - Agropecuária | Q32: 1º ANO A - Informática | R32: 1º ANO B - Informática | S32: 2º ANO A - Informática | T32: 2º ANO B - Informática | U32: 3º ANO A - Informática | V32: 3º ANO B - Informática | X32: 1º ANO - Química | Z32: 1º ANO - Meio Ambiente
A33: QUARTA-FEIRA | B33: 07:20 - 08:10 | C33: Língua Portuguesa (Ana Clara) (2/1) | D33: Ciência e Tecnologia de Produtos de Origem Vegetal (Márcia Antunes) (Agroin. 2) | E33: Química (Cristiane)(1/6) | F33: Sociologia (Márlio)(1/7) | G33: Anál. Sensorial (Daniela) (Sl. Análise Sensorial) | H33: Tecnologia de Leite (Ramon) (Agroin. 1) | J33: Zootecnia Geral e Pequenas Criações (Paulo Eduardo) (Zoo I) | K33: Química (Luiz Fernando)(2/3) | L33: Máquinas Agrícolas (Cani) (Agricult. I) | M33: Matemática (Eilson Santiago) (1/9) | N33: Construções Rurais e Ambiência (Leandro / Rodrigo Nogueira) (Sala de Topografia) | O33: Matemática (Viviane)(1/15) | Q33: Língua Portuguesa (Mayara) (2/4) | R33: Matemática (Kélcio)(2/5) | S33: Química (Aline) (1/10) | T33: Língua Portuguesa (Patrícia Ramires) (1/11) | U33: Redes de comput. (Jamerson Jardel) (Lab. Redes) | V33: Geografia (Márcia Martins)(1/17) | X33: Química Geral e Inorgânica (Willian Andrade)(1/4) | Z33: Geografia (Tiago Caminha)(1/5)
B34: 08:10 - 09:00 | C34: Língua Portuguesa (Ana Clara) (2/1) | D34: Ciência e Tecnologia de Produtos de Origem Vegetal (Márcia Antunes) (Agroin. 2) | E34: Química (Cristiane)(1/6) | F34: Sociologia (Márlio)(1/7) | G34: Anál. Sensorial (Daniela) (Sl. Análise Sensorial) | H34: Tecnologia de Leite (Ramon) (Agroin. 1) | J34: Zootecnia Geral e Pequenas Criações (Paulo Eduardo) (Zoo I) | K34: Química (Luiz Fernando)(2/3) | L34: Máquinas Agrícolas (Cani) (Agricult. I) | M34: Matemática (Eilson Santiago) (1/9) | N34: Construções Rurais e Ambiência (Leandro / Rodrigo Nogueira) (Sala de Topografia) | O34: Física (Clayton) (1/15) | Q34: Língua Portuguesa (Mayara) (2/4) | R34: Matemática (Kélcio)(2/5) | S34: Química (Aline) (1/10) | T34: Biologia (Lays) (1/11) | U34: Redes de comput. (Jamerson Jardel) (Lab. Redes) | V34: Geografia (Márcia Martins)(1/17) | X34: Química Geral e Inorgânica (Willian Andrade)(1/4) | Z34: Geografia (Tiago Caminha)(1/5)
B35: INTERVALO
B36: 09:20 - 10:10 | C36: Literatura (Mayara)(2/1) | D36: Língua Portuguesa (Ana Clara) (2/2) | E36: Sociologia (Márlio) (1/6) | F36: História (Rosana) (1/7) | G36: Tecnologia de Leite (Ramon) (Agroin. 1) | H36: Anál. Sensorial (Daniela) (Sl. Análise Sensorial) | J36: Língua Portuguesa (Cláudia) (2/3) | K36: Zootecnia Geral e Pequenas Criações (Paulo Eduardo) (Zoo I) | L36: Matemática (Eilson Santiago) (1/8) | M36: Física (Clayton) (1/9) | N36: Matemática (Nilsa) (1/14) | O36: Construções Rurais e Ambiência (Leandro / Rodrigo Nogueira) (Sala de Topografia) | Q36: Literatura (Wesley) (2/4) | S36: Língua Portuguesa (Patrícia Ramires) (1/10) | T36: Biologia (Lays) (1/11) | U36: Geografia (Márcia Martins)(1/16) | V36: Redes de comput. (Jamerson Jardel) (Lab. Redes) | X36: Projeto Integrador I - Química e Sociedade (Cristiane/Lucas Fernando)(1/4) | Z36: Língua Inglesa (Adailton)(1/5)
B37: 10:10 - 11:00 | C37: Geografia (Tiago Caminha)(2/1) | D37: Língua Portuguesa (Ana Clara) (2/2) | E37: Sociologia (Márlio) (1/6) | F37: Língua Portuguesa (Patrícia Ramires) (1/7) | G37: Tecnologia de Leite (Ramon) (Agroin. 1) | H37: Anál. Sensorial (Daniela) (Sl. Análise Sensorial) | J37: Química (Luiz Fernando) (2/3) | K37: Zootecnia Geral e Pequenas Criações (Paulo Eduardo) (Zoo I) | L37: História (Rosana) (1/8) | M37: Física (Clayton) (1/9) | N37: Matemática (Nilsa) (1/14) | O37: Construções Rurais e Ambiência (Leandro / Rodrigo Nogueira) (Sala de Topografia) | Q37: Literatura (Wesley) (2/4) | R37: Língua Portuguesa (Mayara) (2/5) | S37: Biologia (Lays) (1/10) | T37: Química (Aline) (1/11) | U37: Geografia (Márcia Martins)(1/16) | V37: Redes de comput. (Jamerson Jardel) (Lab. Redes) | X37: Língua Inglesa (Adailton)(1/4) | Z37: Química (Willian Andrade)(1/5)
B38: 11:00 - 11:50 | C38: Geografia (Tiago Caminha)(2/1) | D38: Ciência e Tecnologia de Produtos de Origem Vegetal (Márcia Antunes) (Agroin. 2) | E38: Língua Portuguesa (Patrícia Ramires) (1/6) | F38: Matemática (Aldemi) (1/7) | G38: Sociologia (Patrícia Lima) (1/12) | H38: Matemática (Nilsa) (1/13) | J38: Química (Luiz Fernando) (2/3) | K38: Língua Portuguesa (Cláudia) (2/4) | L38: História (Rosana) (1/8) | M38: Literatura (Wesley) (1/9) | N38: Física (Clayton) (1/14) | O38: Matemática (Viviane)(1/15) | Q38: Língua Inglesa (Adailton) (2/4) | R38: Língua Portuguesa (Mayara) (2/5) | S38: Biologia (Lays) (1/10) | T38: Química (Aline) (1/11) | U38: Língua Portuguesa (Ana Clara) (1/16) | V38: Redes de comput. (Jamerson Jardel) (Lab. Redes) | X38: Língua Portuguesa (Willian Fernandes)(1/4) | Z38: Química (Willian Andrade)(1/5)
B39: ALMOÇO
B40: 13:20 - 14:10
...

Sheet Ensalamento - Geral
C1: (1/3) | J1: CH - Total
A2: # | B2: # | C2: HORÁRIO | D2: SEG | E2: TER | F2: QUA | G2: QUI | H2: SEX | J2: =(75-(COUNTIF(D5:H24,"Janela")))&" h/a" -> 4 h/a
D3: 3-16 | E3: 17-30 | F3: 31-44 | G3: 45-58 | H3: 59-72
D4: 3-22 | E4: 23-42 | F4: 43-62 | G4: 63-82 | H4: 83-102
A5: 15 | B5: 21 | C5: 07:20 - 08:10 | D5: =IF((COUNTIF('Horário - Graduação'!$C3:$AW3,"*"&$C$1&"*")+COUNTIF('Horário - Ensino Médio'!$C3:$Z3,"*"&$C$1&"*"))>1,CONCAT("[CHOQUE] - ",IFERROR(HLOOKUP("*"&$C$1&"*",'Horário - Graduação'!$C3:$AW$23,$B5,FALSE),IFERROR(HLOOKUP("*"&$C$1&"*",'Horário - Ensino Médio'!$C3:$Z$17,$A5,FALSE),"Janela"))),IFERROR(HLOOKUP("*"&$C$1&"*",'Horário - Graduação'!$C3:$AW$23,$B5,FALSE),IFERROR(HLOOKUP("*"&$C$1&"*",'Horário - Ensino Médio'!$C3:$Z$17,$A5,FALSE),"Janela"))) -> Janela | E5: =IF((COUNTIF('Horário - Graduação'!$C24:$AW24,"*"&$C$1&"*")+COUNTIF('Horário - Ensino Médio'!$C18:$Z18,"*"&$C$1&"*"))>1,CONCAT("[CHOQUE] - ",IFERROR(HLOOKUP("*"&$C$1&"*",'Horário - Graduação'!$C24:$AW$44,$B5,FALSE),IFERROR(HLOOKUP("*"&$C$1&"*",'Horário - Ensino Médio'!$C18:$Z$32,$A5,FALSE),"Janela"))),IFERROR(HLOOKUP("*"&$C$1&"*",'Horário - Graduação'!$C24:$AW$44,$B5,FALSE),IFERROR(HLOOKUP("*"&$C$1&"*",'Horário - Ensino Médio'!$C18:$Z$32,$A5,FALSE),"Janela"))) -> Janela | F5: =IF((COUNTIF('Horário - Graduação'!$C45:$AW45,"*"&$C$1&"*")+COUNTIF('Horário - Ensino Médio'!$C33:$Z33,"*"&$C$1&"*"))>1,CONCAT("[CHOQUE] - ",IFERROR(HLOOKUP("*"&$C$1&"*",'Horário - Graduação'!$C45:$AW$65,$B5,FALSE),IFERROR(HLOOKUP("*"&$C$1&"*",'Horário - Ensino Médio'!$C33:$Z$47,$A5,FALSE),"Janela"))),IFERROR(HLOOKUP("*"&$C$1&"*",'Horário - Graduação'!$C45:$AW$65,$B5,FALSE),IFERROR(HLOOKUP("*"&$C$1&"*",'Horário - Ensino Médio'!$C33:$Z$47,$A5,FALSE),"Janela"))) -> Janela | G5: =IF((COUNTIF('Horário - Graduação'!$C66:$AW66,"*"&$C$1&"*")+COUNTIF('Horário - Ensino Médio'!$C48:$Z48,"*"&$C$1&"*"))>1,CONCAT("[CHOQUE] - ",IFERROR(HLOOKUP("*"&$C$1&"*",'Horário - Graduação'!$C66:$AW$86,$B5,FALSE),IFERROR(HLOOKUP("*"&$C$1&"*",'Horário - Ensino Médio'!$C48:$Z$62,$A5,FALSE),"Janela"))),IFERROR(HLOOKUP("*"&$C$1&"*",'Horário - Graduação'!$C66:$AW$86,$B5,FALSE),IFERROR(HLOOKUP("*"&$C$1&"*",'Horário - Ensino Médio'!$C48:$Z$62,$A5,FALSE),"Janela"))) -> Janela | H5: =IF((COUNTIF('Horário - Graduação'!$C87:$AW87,"*"&$C$1&"*")+COUNTIF('Horário - Ensino Médio'!$C63:$Z63,"*"&$C$1&"*"))>1,CONCAT("[CHOQUE] - ",IFERROR(HLOOKUP("*"&$C$1&"*",'Horário - Graduação'!$C87:$AW$107,$B5,FALSE),IFERROR(HLOOKUP("*"&$C$1&"*",'Horário - Ensino Médio'!$C63:$Z$77,$A5,FALSE),"Janela"))),IFERROR(HLOOKUP("*"&$C$1&"*",'Horário - Graduação'!$C87:$AW$107,$B5,FALSE),IFERROR(HLOOKUP("*"&$C$1&"*",'Horário - Ensino Médio'!$C63:$Z$77,$A5,FALSE),"Janela"))) -> Janela
A6: 14 | B6: 20 | C6: 08:10 - 09:00 | D6: =IF((COUNTIF('Horário - Graduação'!$C4:$AW4,"*"&$C$1&"*")+COUNTIF('Horário - Ensino Médio'!$C4:$Z4,"*"&$C$1&"*"))>1,CONCAT("[CHOQUE] - ",IFERROR(HLOOKUP("*"&$C$1&"*",'Horário - Graduação'!$C4:$AW$23,$B6,FALSE),IFERROR(HLOOKUP("*"&$C$1&"*",'Horário - Ensino Médio'!$C4:$Z$17,$A6,FALSE),"Janela"))),IFERROR(HLOOKUP("*"&$C$1&"*",'Horário - Graduação'!$C4:$AW$23,$B6,FALSE),IFERROR(HLOOKUP("*"&$C$1&"*",'Horário - Ensino Médio'!$C4:$Z$17,$A6,FALSE),"Janela"))) -> Janela | E6: =IF((COUNTIF('Horário - Graduação'!$C25:$AW25,"*"&$C$1&"*")+COUNTIF('Horário - Ensino Médio'!$C19:$Z19,"*"&$C$1&"*"))>1,CONCAT("[CHOQUE] - ",IFERROR(HLOOKUP("*"&$C$1&"*",'Horário - Graduação'!$C25:$AW$44,$B6,FALSE),IFERROR(HLOOKUP("*"&$C$1&"*",'Horário - Ensino Médio'!$C19:$Z$32,$A6,FALSE),"Janela"))),IFERROR(HLOOKUP("*"&$C$1&"*",'Horário - Graduação'!$C25:$AW$44,$B6,FALSE),IFERROR(HLOOKUP("*"&$C$1&"*",'Horário - Ensino Médio'!$C19:$Z$32,$A6,FALSE),"Janela"))) -> Janela | F6: =IF((COUNTIF('Horário - Graduação'!$C46:$AW46,"*"&$C$1&"*")+COUNTIF('Horário - Ensino Médio'!$C34:$Z34,"*"&$C$1&"*"))>1,CONCAT("[CHOQUE] - ",IFERROR(HLOOKUP("*"&$C$1&"*",'Horário - Graduação'!$C46:$AW$65,$B6,FALSE),IFERROR(HLOOKUP("*"&$C$1&"*",'Horário - Ensino Médio'!$C34:$Z$47,$A6,FALSE),"Janela"))),IFERROR(HLOOKUP("*"&$C$1&"*",'Horário - Graduação'!$C46:$AW$65,$B6,FALSE),IFERROR(HLOOKUP("*"&$C$1&"*",'Horário - Ensino Médio'!$C34:$Z$47,$A6,FALSE),"Janela"))) -> Janela | G6: =IF((COUNTIF('Horário - Graduação'!$C67:$AW67,"*"&$C$1&"*")+COUNTIF('Horário - Ensino Médio'!$C49:$Z49,"*"&$C$1&"*"))>1,CONCAT("[CHOQUE] - ",IFERROR(HLOOKUP("*"&$C$1&"*",'Horário - Graduação'!$C67:$AW$86,$B6,FALSE),IFERROR(HLOOKUP("*"&$C$1&"*",'Horário - Ensino Médio'!$C49:$Z$62,$A6,FALSE),"Janela"))),IFERROR(HLOOKUP("*"&$C$1&"*",'Horário - Graduação'!$C67:$AW$86,$B6,FALSE),IFERROR(HLOOKUP("*"&$C$1&"*",'Horário - Ensino Médio'!$C49:$Z$62,$A6,FALSE),"Janela"))) -> Janela | H6: =IF((COUNTIF('Horário - Graduação'!$C88:$AW88,"*"&$C$1&"*")+COUNTIF('Horário - Ensino Médio'!$C64:$Z64,"*"&$C$1&"*"))>1,CONCAT("[CHOQUE] - ",IFERROR(HLOOKUP("*"&$C$1&"*",'Horário - Graduação'!$C88:$AW$107,$B6,FALSE),IFERROR(HLOOKUP("*"&$C$1&"*",'Horário - Ensino Médio'!$C64:$Z$77,$A6,FALSE),"Janela"))),IFERROR(HLOOKUP("*"&$C$1&"*",'Horário - Graduação'!$C88:$AW$107,$B6,FALSE),IFERROR(HLOOKUP("*"&$C$1&"*",'Horário - Ensino Médio'!$C64:$Z$77,$A6,FALSE),"Janela"))) -> Janela
A7: 13 | B7: 19 | C7: INTERVALO | D7: INTERVALO | E7: INTERVALO | F7: INTERVALO | G7: INTERVALO | H7: INTERVALO
A8: 12 | B8: 18 | C8: 09:20 - 10:10 | D8: =IF((COUNTIF('Horário - Graduação'!$C6:$AW6,"*"&$C$1&"*")+COUNTIF('Horário - Ensino Médio'!$C6:$Z6,"*"&$C$1&"*"))>1,CONCAT("[CHOQUE] - ",IFERROR(HLOOKUP("*"&$C$1&"*",'Horário - Graduação'!$C6:$AW$23,$B8,FALSE),IFERROR(HLOOKUP("*"&$C$1&"*",'Horário - Ensino Médio'!$C6:$Z$17,$A8,FALSE),"Janela"))),IFERROR(HLOOKUP("*"&$C$1&"*",'Horário - Graduação'!$C6:$AW$23,$B8,FALSE),IFERROR(HLOOKUP("*"&$C$1&"*",'Horário - Ensino Médio'!$C6:$Z$17,$A8,FALSE),"Janela"))) -> Janela | E8: =IF((COUNTIF('Horário - Graduação'!$C27:$AW27,"*"&$C$1&"*")+COUNTIF('Horário - Ensino Médio'!$C21:$Z21,"*"&$C$1&"*"))>1,CONCAT("[CHOQUE] - ",IFERROR(HLOOKUP("*"&$C$1&"*",'Horário - Graduação'!$C27:$AW$44,$B8,FALSE),IFERROR(HLOOKUP("*"&$C$1&"*",'Horário - Ensino Médio'!$C21:$Z$32,$A8,FALSE),"Janela"))),IFERROR(HLOOKUP("*"&$C$1&"*",'Horário - Graduação'!$C27:$AW$44,$B8,FALSE),IFERROR(HLOOKUP("*"&$C$1&"*",'Horário - Ensino Médio'!$C21:$Z$32,$A8,FALSE),"Janela"))) -> Janela | F8: =IF((COUNTIF('Horário - Graduação'!$C48:$AW48,"*"&$C$1&"*")+COUNTIF('Horário - Ensino Médio'!$C36:$Z36,"*"&$C$1&"*"))>1,CONCAT("[CHOQUE] - ",IFERROR(HLOOKUP("*"&$C$1&"*",'Horário - Graduação'!$C48:$AW$65,$B8,FALSE),IFERROR(HLOOKUP("*"&$C$1&"*",'Horário - Ensino Médio'!$C36:$Z$47,$A8,FALSE),"Janela"))),IFERROR(HLOOKUP("*"&$C$1&"*",'Horário - Graduação'!$C48:$AW$65,$B8,FALSE),IFERROR(HLOOKUP("*"&$C$1&"*",'Horário - Ensino Médio'!$C36:$Z$47,$A8,FALSE),"Janela"))) -> Janela | G8: =IF((COUNTIF('Horário - Graduação'!$C69:$AW69,"*"&$C$1&"*")+COUNTIF('Horário - Ensino Médio'!$C51:$Z51,"*"&$C$1&"*"))>1,CONCAT("[CHOQUE] - ",IFERROR(HLOOKUP("*"&$C$1&"*",'Horário - Graduação'!$C69:$AW$86,$B8,FALSE),IFERROR(HLOOKUP("*"&$C$1&"*",'Horário - Ensino Médio'!$C51:$Z$62,$A8,FALSE),"Janela"))),IFERROR(HLOOKUP("*"&$C$1&"*",'Horário - Graduação'!$C69:$AW$86,$B8,FALSE),IFERROR(HLOOKUP("*"&$C$1&"*",'Horário - Ensino Médio'!$C51:$Z$62,$A8,FALSE),"Janela"))) -> Janela | H8: =IF((COUNTIF('Horário - Graduação'!$C90:$AW90,"*"&$C$1&"*")+COUNTIF('Horário - Ensino Médio'!$C66:$Z66,"*"&$C$1&"*"))>1,CONCAT("[CHOQUE] - ",IFERROR(HLOOKUP("*"&$C$1&"*",'Horário - Graduação'!$C90:$AW$107,$B8,FALSE),IFERROR(HLOOKUP("*"&$C$1&"*",'Horário - Ensino Médio'!$C66:$Z$77,$A8,FALSE),"Janela"))),IFERROR(HLOOKUP("*"&$C$1&"*",'Horário - Graduação'!$C90:$AW$107,$B8,FALSE),IFERROR(HLOOKUP("*"&$C$1&"*",'Horário - Ensino Médio'!$C66:$Z$77,$A8,FALSE),"Janela"))) -> Janela
A9: 11 | B9: 17 | C9: 10:10 - 11:00 | D9: =IF((COUNTIF('Horário - Graduação'!$C7:$AW7,"*"&$C$1&"*")+COUNTIF('Horário - Ensino Médio'!$C7:$Z7,"*"&$C$1&"*"))>1,CONCAT("[CHOQUE] - ",IFERROR(HLOOKUP("*"&$C$1&"*",'Horário - Graduação'!$C7:$AW$23,$B9,FALSE),IFERROR(HLOOKUP("*"&$C$1&"*",'Horário - Ensino Médio'!$C7:$Z$17,$A9,FALSE),"Janela"))),IFERROR(HLOOKUP("*"&$C$1&"*",'Horário - Graduação'!$C7:$AW$23,$B9,FALSE),IFERROR(HLOOKUP("*"&$C$1&"*",'Horário - Ensino Médio'!$C7:$Z$17,$A9,FALSE),"Janela"))) -> Janela | E9: =IF((COUNTIF('Horário - Graduação'!$C28:$AW28,"*"&$C$1&"*")+COUNTIF('Horário - Ensino Médio'!$C22:$Z22,"*"&$C$1&"*"))>1,CONCAT("[CHOQUE] - ",IFERROR(HLOOKUP("*"&$C$1&"*",'Horário - Graduação'!$C28:$AW$44,$B9,FALSE),IFERROR(HLOOKUP("*"&$C$1&"*",'Horário - Ensino Médio'!$C22:$Z$32,$A9,FALSE),"Janela"))),IFERROR(HLOOKUP("*"&$C$1&"*",'Horário - Graduação'!$C28:$AW$44,$B9,FALSE),IFERROR(HLOOKUP("*"&$C$1&"*",'Horário - Ensino Médio'!$C22:$Z$32,$A9,FALSE),"Janela"))) -> Janela | F9: =IF((COUNTIF('Horário - Graduação'!$C49:$AW49,"*"&$C$1&"*")+COUNTIF('Horário - Ensino Médio'!$C37:$Z37,"*"&$C$1&"*"))>1,CONCAT("[CHOQUE] - ",IFERROR(HLOOKUP("*"&$C$1&"*",'Horário - Graduação'!$C49:$AW$65,$B9,FALSE),IFERROR(HLOOKUP("*"&$C$1&"*",'Horário - Ensino Médio'!$C37:$Z$47,$A9,FALSE),"Janela"))),IFERROR(HLOOKUP("*"&$C$1&"*",'Horário - Graduação'!$C49:$AW$65,$B9,FALSE),IFERROR(HLOOKUP("*"&$C$1&"*",'Horário - Ensino Médio'!$C37:$Z$47,$A9,FALSE),"Janela"))) -> Janela | G9: =IF((COUNTIF('Horário - Graduação'!$C70:$AW70,"*"&$C$1&"*")+COUNTIF('Horário - Ensino Médio'!$C52:$Z52,"*"&$C$1&"*"))>1,CONCAT("[CHOQUE] - ",IFERROR(HLOOKUP("*"&$C$1&"*",'Horário - Graduação'!$C70:$AW$86,$B9,FALSE),IFERROR(HLOOKUP("*"&$C$1&"*",'Horário - Ensino Médio'!$C52:$Z$62,$A9,FALSE),"Janela"))),IFERROR(HLOOKUP("*"&$C$1&"*",'Horário - Graduação'!$C70:$AW$86,$B9,FALSE),IFERROR(HLOOKUP("*"&$C$1&"*",'Horário - Ensino Médio'!$C52:$Z$62,$A9,FALSE),"Janela"))) -> Janela | H9: =IF((COUNTIF('Horário - Graduação'!$C91:$AW91,"*"&$C$1&"*")+COUNTIF('Horário - Ensino Médio'!$C67:$Z67,"*"&$C$1&"*"))>1,CONCAT("[CHOQUE] - ",IFERROR(HLOOKUP("*"&$C$1&"*",'Horário - Graduação'!$C91:$AW$107,$B9,FALSE),IFERROR(HLOOKUP("*"&$C$1&"*",'Horário - Ensino Médio'!$C67:$Z$77,$A9,FALSE),"Janela"))),IFERROR(HLOOKUP("*"&$C$1&"*",'Horário - Graduação'!$C91:$AW$107,$B9,FALSE),IFERROR(HLOOKUP("*"&$C$1&"*",'Horário - Ensino Médio'!$C67:$Z$77,$A9,FALSE),"Janela"))) -> Janela
A10: 10 | B10: 16 | C10: 11:00 - 11:50 | D10: =IF((COUNTIF('Horário - Graduação'!$C8:$AW8,"*"&$C$1&"*")+COUNTIF('Horário - Ensino Médio'!$C8:$Z8,"*"&$C$1&"*"))>1,CONCAT("[CHOQUE] - ",IFERROR(HLOOKUP("*"&$C$1&"*",'Horário - Graduação'!$C8:$AW$23,$B10,FALSE),IFERROR(HLOOKUP("*"&$C$1&"*",'Horário - Ensino Médio'!$C8:$Z$17,$A10,FALSE),"Janela"))),IFERROR(HLOOKUP("*"&$C$1&"*",'Horário - Graduação'!$C8:$AW$23,$B10,FALSE),IFERROR(HLOOKUP("*"&$C$1&"*",'Horário - Ensino Médio'!$C8:$Z$17,$A10,FALSE),"Janela"))) -> Janela | E10: =IF((COUNTIF('Horário - Graduação'!$C29:$AW29,"*"&$C$1&"*")+COUNTIF('Horário - Ensino Médio'!$C23:$Z23,"*"&$C$1&"*"))>1,CONCAT("[CHOQUE] - ",IFERROR(HLOOKUP("*"&$C$1&"*",'Horário - Graduação'!$C29:$AW$44,$B10,FALSE),IFERROR(HLOOKUP("*"&$C$1&"*",'Horário - Ensino Médio'!$C23:$Z$32,$A10,FALSE),"Janela"))),IFERROR(HLOOKUP("*"&$C$1&"*",'Horário - Graduação'!$C29:$AW$44,$B10,FALSE),IFERROR(HLOOKUP("*"&$C$1&"*",'Horário - Ensino Médio'!$C23:$Z$32,$A10,FALSE),"Janela"))) -> Janela | F10: =IF((COUNTIF('Horário - Graduação'!$C50:$AW50,"*"&$C$1&"*")+COUNTIF('Horário - Ensino Médio'!$C38:$Z38,"*"&$C$1&"*"))>1,CONCAT("[CHOQUE] - ",IFERROR(HLOOKUP("*"&$C$1&"*",'Horário - Graduação'!$C50:$AW$65,$B10,FALSE),IFERROR(HLOOKUP("*"&$C$1&"*",'Horário - Ensino Médio'!$C38:$Z$47,$A10,FALSE),"Janela"))),IFERROR(HLOOKUP("*"&$C$1&"*",'Horário - Graduação'!$C50:$AW$65,$B10,FALSE),IFERROR(HLOOKUP("*"&$C$1&"*",'Horário - Ensino Médio'!$C38:$Z$47,$A10,FALSE),"Janela"))) -> Janela | G10: =IF((COUNTIF('Horário - Graduação'!$C71:$AW71,"*"&$C$1&"*")+COUNTIF('Horário - Ensino Médio'!$C53:$Z53,"*"&$C$1&"*"))>1,CONCAT("[CHOQUE] - ",IFERROR(HLOOKUP("*"&$C$1&"*",'Horário - Graduação'!$C71:$AW$86,$B10,FALSE),IFERROR(HLOOKUP("*"&$C$1&"*",'Horário - Ensino Médio'!$C53:$Z$62,$A10,FALSE),"Janela"))),IFERROR(HLOOKUP("*"&$C$1&"*",'Horário - Graduação'!$C71:$AW$86,$B10,FALSE),IFERROR(HLOOKUP("*"&$C$1&"*",'Horário - Ensino Médio'!$C53:$Z$62,$A10,FALSE),"Janela"))) -> Janela | H10: =IF((COUNTIF('Horário - Graduação'!$C92:$AW92,"*"&$C$1&"*")+COUNTIF('Horário - Ensino Médio'!$C68:$Z68,"*"&$C$1&"*"))>1,CONCAT("[CHOQUE] - ",IFERROR(HLOOKUP("*"&$C$1&"*",'Horário - Graduação'!$C92:$AW$107,$B10,FALSE),IFERROR(HLOOKUP("*"&$C$1&"*",'Horário - Ensino Médio'!$C68:$Z$77,$A10,FALSE),"Janela"))),IFERROR(HLOOKUP("*"&$C$1&"*",'Horário - Graduação'!$C92:$AW$107,$B10,FALSE),IFERROR(HLOOKUP("*"&$C$1&"*",'Horário - Ensino Médio'!$C68:$Z$77,$A10,FALSE),"Janela"))) -> Janela
A11: 9 | B11: 15 | C11: ALMOÇO | D11: ALMOÇO | E11: ALMOÇO | F11: ALMOÇO | G11: ALMOÇO | H11: ALMOÇO
A12: 8 | B12: 14 | C12: 13:20 - 14:10 | D12: =IF((COUNTIF('Horário - Graduação'!$C10:$AW10,"*"&$C$1&"*")+COUNTIF('Horário - Ensino Médio'!$C10:$Z10,"*"&$C$1&"*"))>1,CONCAT("[CHOQUE] - ",IFERROR(HLOOKUP("*"&$C$1&"*",'Horário - Graduação'!$C10:$AW$23,$B12,FALSE),IFERROR(HLOOKUP("*"&$C$1&"*",'Horário - Ensino Médio'!$C10:$Z$17,$A12,FALSE),"Janela"))),IFERROR(HLOOKUP("*"&$C$1&"*",'Horário - Graduação'!$C10:$AW$23,$B12,FALSE),IFERROR(HLOOKUP("*"&$C$1&"*",'Horário - Ensino Médio'!$C10:$Z$17,$A12,FALSE),"Janela"))) -> Janela | E12: =IF((COUNTIF('Horário - Graduação'!$C31:$AW31,"*"&$C$1&"*")+COUNTIF('Horário - Ensino Médio'!$C25:$Z25,"*"&$C$1&"*"))>1,CONCAT("[CHOQUE] - ",IFERROR(HLOOKUP("*"&$C$1&"*",'Horário - Graduação'!$C31:$AW$44,$B12,FALSE),IFERROR(HLOOKUP("*"&$C$1&"*",'Horário - Ensino Médio'!$C25:$Z$32,$A12,FALSE),"Janela"))),IFERROR(HLOOKUP("*"&$C$1&"*",'Horário - Graduação'!$C31:$AW$44,$B12,FALSE),IFERROR(HLOOKUP("*"&$C$1&"*",'Horário - Ensino Médio'!$C25:$Z$32,$A12,FALSE),"Janela"))) -> Janela | F12: =IF((COUNTIF('Horário - Graduação'!$C52:$AW52,"*"&$C$1&"*")+COUNTIF('Horário - Ensino Médio'!$C40:$Z40,"*"&$C$1&"*"))>1,CONCAT("[CHOQUE] - ",IFERROR(HLOOKUP("*"&$C$1&"*",'Horário - Graduação'!$C52:$AW$65,$B12,FALSE),IFERROR(HLOOKUP("*"&$C$1&"*",'Horário - Ensino Médio'!$C40:$Z$47,$A12,FALSE),"Janela"))),IFERROR(HLOOKUP("*"&$C$1&"*",'Horário - Graduação'!$C52:$AW$65,$B12,FALSE),IFERROR(HLOOKUP("*"&$C$1&"*",'Horário - Ensino Médio'!$C40:$Z$47,$A12,FALSE),"Janela"))) -> Janela | G12: =IF((COUNTIF('Horário - Graduação'!$C73:$AW73,"*"&$C$1&"*")+COUNTIF('Horário - Ensino Médio'!$C55:$Z55,"*"&$C$1&"*"))>1,CONCAT("[CHOQUE] - ",IFERROR(HLOOKUP("*"&$C$1&"*",'Horário - Graduação'!$C73:$AW$86,$B12,FALSE),IFERROR(HLOOKUP("*"&$C$1&"*",'Horário - Ensino Médio'!$C55:$Z$62,$A12,FALSE),"Janela"))),IFERROR(HLOOKUP("*"&$C$1&"*",'Horário - Graduação'!$C73:$AW$86,$B12,FALSE),IFERROR(HLOOKUP("*"&$C$1&"*",'Horário - Ensino Médio'!$C55:$Z$62,$A12,FALSE),"Janela"))) -> Janela | H12: =IF((COUNTIF('Horário - Graduação'!$C94:$AW94,"*"&$C$1&"*")+COUNTIF(#REF!,"*"&$C$1&"*"))>1,CONCAT("[CHOQUE] - ",IFERROR(HLOOKUP("*"&$C$1&"*",'Horário - Graduação'!$C94:$AW$107,$B12,FALSE),IFERROR(HLOOKUP("*"&$C$1&"*",'Horário - Ensino Médio'!$C75:$Z$77,$A12,FALSE),"Janela"))),IFERROR(HLOOKUP("*"&$C$1&"*",'Horário - Graduação'!$C94:$AW$107,$B12,FALSE),IFERROR(HLOOKUP("*"&$C$1&"*",'Horário - Ensino Médio'!$C75:$Z$77,$A12,FALSE),"Janela"))) -> #REF!
